Workbook
Name Slicer_Region: #N/A
Name Slicer_Sales_Channel: #N/A

Sheet Supplier
A1: Supplier_ID | B1: Supplier_Name | C1: Contact_Person | D1: Phone | E1: Email | F1: City | G1: Lead_Time_Days | H1: Rating | I1: Status
A2: SUP001 | B2: Anna Agro Pvt Ltd | C2: Madhavan Rao | D2: 9826600539 | E2: madhavan.anna@agromail.com | F2: Salem | G2: 4 | H2: 4.3 | I2: Active
A3: SUP002 | B3: Palani Suppliers Pvt Ltd | C3: Kamala Subramaniam | D3: 9349817734 | E3: kamala.palani@suppliersmail.com | F3: Coimbatore | G3: 2 | H3: 2.7 | I3: Active
A4: SUP003 | B4: Saravana Beverages Pvt Ltd | C4: Hari Mudaliar | D4: 9732719211 | E4: hari.saravana@beveragesmail.com | F4: Kochi | G4: 8 | H4: 3.1 | I4: Active
A5: SUP004 | B5: Coastal Household Products Pvt Ltd | C5: Aishwarya Naicker | D5: 9398362082 | E5: aishwarya.coastal@householdmail.com | F5: Madurai | G5: 13 | H5: 3.6 | I5: Active
A6: SUP005 | B6: Vel Traders Pvt Ltd | C6: Padma Raj | D6: 9469319644 | E6: padma.vel@bizcom | F6: Chennai | G6: 8 | H6: 2.7 | I6: Active
A7: SUP006 | B7: Kovai Distributors Pvt Ltd | C7: Vasanthi Venkataraman | D7: 9506448196 | E7: vasanthi.kovai@distributorsmail.com | F7: Kochi | G7: 45 | H7: 4.9 | I7: Active
A8: SUP007 | B8: Om Fresh Produce Pvt Ltd | C8: Raghav Prabhu | D8: 9174684276 | E8: raghav.om@freshmail.com | F8: Tiruppur | G8: 11 | H8: 3 | I8: Active
A9: SUP008 | B9: Sree Snacks Co Pvt Ltd | C9: Naveen Devi | D9: 9398471886 | E9: naveen.sree@snacksmail.com | F9: Salem | G9: 15 | H9: 2.8 | I9: Active
A10: SUP009 | B10: Ganesh Snacks Co Pvt Ltd | C10: Chitra Gupta | D10: 9853573823 | E10: chitra.ganesh@snacksmail.com | F10: Tiruppur | G10: 5 | H10: 4.2 | I10: Active
A11: SUP010 | B11: Bharat Snacks Co Pvt Ltd | C11: Raghav Pillai | D11: 9596348124 | E11: raghav.bharat@snacksmail.com | F11: Kochi | G11: 13 | H11: 3.1 | I11: Active
A12: SUP011 | B12: Malabar Distributors Pvt Ltd | C12: Nandhini Mudaliar | D12: 9924970419 | E12: nandhini.malabar@distributorsmail.com | F12: Kochi | G12: 5 | H12: 4.2 | I12: Active
A13: SUP012 | B13: Tirupati Foods Pvt Ltd | C13: Karthik Naicker | D13: 9326541099 | E13: karthik.tirupati@foodsmail.com | F13: Tiruppur | G13: 8 | H13: 3.2 | I13: Active
... A86: SUP085 | B86: Anna Traders Pvt Ltd | C86: Ezhil Menon | D86: 9707665448 | E86: ezhil.anna@tradersmail.com | F86: Hyderabad | G86: 14 | H86: 2.8 | I86: Active

Sheet Store
A1: Store_ID | B1: Store_Name | C1: Manager | D1: Region | E1: City | F1: State | G1: Store_Type | H1: Opening_Date | I1: Monthly_Target | J1: Status
A2: STR001 | B2: FreshMart Madurai Crossing | C2: Sudha Naicker | D2: South | E2: Madurai | F2: Tamil Nadu | G2: Supermarket | H2: 42147 | I2: 1921769 | J2: Active
A3: STR002 | B3: FreshMart Tiruppur Bypass | C3: Manoj Nair | D3: South | E3: Tiruppur | F3: Tamil Nadu | G3: Convenience | H3: 42633 | I3: 591044 | J3: Active
A4: STR003 | B4: FreshMart Tiruppur Square | C4: Suresh Nathan | D4: South | E4: Tiruppur | F4: Tamil Nadu | G4: Express | H4: 44173 | I4: 890380 | J4: Active
A5: STR004 | B5: FreshMart Erode Plaza | C5: Prakash Kumar | D5: South | E5: Erode | F5: Tamil Nadu | G5: Convenience | H5: 44049 | I5: 584869 | J5: Active
A6: STR005 | B6: FreshMart Chennai Crossing | C6: Lokesh Mudaliar | D6: South | E6: Chennai | F6: Tamil Nadu | G6: Express | H6: 42883 | I6: 983603 | J6: Active
A7: STR006 | B7: FreshMart Mysuru Junction | C7: Senthil Sekar | D7: South | E7: Mysuru | F7: Karnataka | G7: Supermarket | H7: 43856 | I7: 2561982 | J7: Active
A8: STR007 | B8: FreshMart Mysuru Towers | C8: Sudha Sekar | D8: South | E8: Mysuru | F8: Karnataka | G8: Express | H8: 44740 | I8: 988505 | J8: Active
A9: STR008 | B9: FreshMart Kochi Plaza | C9: Malathi Sekar | D9: South | E9: Kochi | F9: Kerala | G9: Supermarket | H9: 44920 | I9: 2481146 | J9: Active
A10: STR009 | B10: FreshMart Kochi Square | C10: Hari Naicker | D10: South | E10: Kochi | F10: Kerala | G10: Convenience | H10: 42974 | I10: 429599 | J10: Active
A11: STR010 | B11: FreshMart Kochi Colony | C11: Bhuvana Naicker | D11: South | E11: Kochi | F11: Kerala | G11: Hypermarket | H11: 42536 | I11: 3928553 | J11: Active
A12: STR011 | B12: FreshMart Bengaluru Enclave | C12: Vasanthi Chandran | D12: South | E12: Bengaluru | F12: Karnataka | G12: Convenience | H12: 43687 | I12: 569084 | J12: Active
A13: STR012 | B13: FreshMart Chennai Junction | C13: Pandi Varma | D13: South | E13: Chennai | F13: Tamil Nadu | G13: Convenience | H13: 43848 | I13: 544019 | J13: Active
... A181: STR180 | B181: FreshMart Guwahati Extension | C181: Suresh Naidu | D181: East | E181: Guwahati | F181: Assam | G181: Hypermarket | H181: 44575 | I181: 4606432 | J181: Active

Sheet Products
A1: Product_ID | B1: Product_Name | C1: Category | D1: Subcategory | E1: Brand | F1: Cost_Price | G1: Selling_Price | H1: Supplier_ID | I1: Season | J1: Status
A2: PRD001 | B2: Local Bakers Buns 1kg | C2: Bakery | D2: Buns | E2: Local Bakers | F2: 184.74 | G2: 299.73 | H2: SUP059 | I2: Summer | J2: Active
A3: PRD002 | B3: Britannia Buns Pack | C3: Bakery | D3: Buns | E3: Britannia | F3: 254.05 | G3: 440.5 | H3: SUP062 | I3: Monsoon | J3: Active
A4: PRD003 | B4: Harvest Gold Buns Combo | C4: Bakery | D4: Buns | E4: Harvest Gold | F4: 343.65 | G4: 589.75 | H4: SUP012 | I4: Winter | J4: Active
A5: PRD004 | B5: Britannia Buns 2kg | C5: Bakery | D5: Buns | E5: Britannia | F5: 236.54 | G5: 398.25 | H5: SUP044 | I5: All Season | J5: Active
A6: PRD005 | B6: Amul Paneer 250ml | C6: Bakery | D6: Buns | E6: Harvest Gold | F6: 205.27 | G6: 332.74 | H6: SUP034 | I6: Winter | J6: Active
A7: PRD006 | B7: Harvest Gold Cookies 500g | C7: Bakery | D7: Cookies | E7: Harvest Gold | F7: 216.32 | G7: 343.56 | H7: SUP031 | I7: Monsoon | J7: Active
A8: PRD007 | B8: Britannia Buns 2kg v2 | C8: Bakery | D8: Buns | E8: Britannia | F8: 265.44 | G8: 437.49 | H8: SUP003 | I8: All Season | J8: Active
A9: PRD008 | B9: Britannia Cookies 200g | C9: Bakery | D9: Cookies | E9: Britannia | F9: 282.88 | G9: 455.79 | H9: SUP075 | I9: Winter | J9: Active
A10: PRD009 | B10: Harvest Gold Buns 200g | C10: Bakery | D10: Buns | E10: Harvest Gold | F10: 398.72 | G10: 661.91 | H10: SUP046 | I10: Monsoon | J10: Active
A11: PRD010 | B11: Harvest Gold Cookies Pack | C11: Bakery | D11: Cookies | E11: Harvest Gold | F11: 107.6 | G11: 182.3 | H11: SUP041 | I11: All Season | J11: Active
A12: PRD011 | B12: Britannia Rusk 1L | C12: Bakery | D12: Rusk | E12: Britannia | F12: 102.23 | G12: 168.36 | H12: SUP076 | I12: Festive | J12: Active
A13: PRD012 | B13: Harvest Gold Rusk 1kg | C13: Bakery | D13: Rusk | E13: Harvest Gold | F13: 336.4 | G13: 541.35 | H13: SUP047 | I13: Summer | J13: Active
... A151: PRD150 | B151: Lizol Toilet Cleaner 200g v2 | C151: Cleaning | D151: Toilet Cleaner | E151: Lizol | F151: 158.06 | G151: 214.04 | H151: SUP021 | I151: All Season | J151: Active

Sheet Employee
A1: Employee_ID | B1: Employee_Name | C1: Gender | D1: Department | E1: Salary | F1: Joining_Date | G1: Store_ID | H1: Employment_Status
A2: EMP0332 | B2: Udhay Gounder | C2: Male | D2: Cashier | E2: 14073 | F2: 42542 | G2: STR149 | H2: Active
A3: EMP0340 | B3: Nithya Subramaniam | C3: Female | D3: Cashier | E3: 14174 | F3: 45193 | G3: STR097 | H3: Active
A4: EMP0157 | B4: Elango Velan | C4: Male | D4: Cashier | E4: 14183 | F4: 43368 | G4: STR012 | H4: Active
A5: EMP0213 | B5: Venkat Varma | C5: Male | D5: Cashier | E5: 14562 | F5: 42739 | G5: STR141 | H5: Active
A6: EMP0319 | B6: Harini Kumar | C6: Female | D6: Cashier | E6: 14584 | F6: 44594 | G6: STR121 | H6: Active
A7: EMP0263 | B7: Vani Nair | C7: Female | D7: Cashier | E7: 14788 | F7: 44212 | G7: STR086 | H7: Active
A8: EMP0018 | B8: Chandran Kumar | C8: Male | D8: Cashier | E8: 14882 | F8: 45471 | G8: STR107 | H8: Active
A9: EMP0058 | B9: Senthil Raj | C9: Male | D9: Cashier | E9: 14977 | F9: 43915 | G9: STR011 | H9: Active
A10: EMP0321 | B10: Sundar Velan | C10: Male | D10: Cashier | E10: 14999 | F10: 45516 | G10: STR064 | H10: Active
A11: EMP0121 | B11: Nithya Selvam | C11: Female | D11: Cashier | E11: 15100 | F11: 45153 | G11: STR085 | H11: Active
A12: EMP0029 | B12: Vasanthi Menon | C12: Female | D12: Cashier | E12: 15131 | F12: 44060 | G12: STR155 | H12: Active
A13: EMP0125 | B13: Nandhini Chettiar | C13: Female | D13: Cashier | E13: 15146 | F13: 46020 | G13: STR138 | H13: Active
... A351: EMP0047 | B351: Sundar Gounder | C351: Male | D351: Store Manager | E351: 67135 | F351: 45398 | G351: STR144 | H351: Active

Sheet Customer
A1: Customer_ID | B1: Customer_Name | C1: Gender | D1: DOB | E1: Phone | F1: Email | G1: City | H1: State | I1: Region | J1: Membership | K1: Registration_Date
A2: CUST0001 | B2: Revathi Balan | C2: Female | D2: 31272 | E2: 9204528821 | F2: revathi1@gmail.com | G2: Coimbatore | H2: Tamil Nadu | I2: South | J2: Bronze | K2: 44659
A3: CUST0002 | B3: Eswari Murugan | C3: Female | D3: 21939 | E3: 9362238769 | F3: eswari2@gmail.com | G3: Tiruppur | H3: Tamil Nadu | I3: South | J3: Silver | K3: 45809
A4: CUST0003 | B4: Banu Balan | C4: Female | D4: 22236 | E4: 9222912620 | F4: banu3@gmail.com | G4: Erode | H4: Tamil Nadu | I4: South | J4: Bronze | K4: 44349
A5: CUST0004 | B5: Naveen Sharma | C5: Male | D5: 21314 | E5: 9806272779 | F5: naveen4@gmail.com | G5: Coimbatore | H5: Tamil Nadu | I5: South | J5: Silver | K5: 44988
A6: CUST0005 | B6: Pandi Raj | C6: Male | D6: 35481 | E6: 9123876200 | F6: pandi5@gmail.com | G6: Guwahati | H6: Assam | I6: East | J6: Silver | K6: 45509
A7: CUST0006 | B7: Thiru Devi | C7: Male | D7: 38850 | E7: 9967934041 | F7: thiru6@gmail.com | G7: Kanpur | H7: Uttar Pradesh | I7: North | J7: Silver | K7: 43501
A8: CUST0007 | B8: Senthil Pillai | C8: Male | D8: 36564 | E8: 9464577685 | F8: senthil7@gmail.com | G8: Salem | H8: Tamil Nadu | I8: South | J8: Silver | K8: 45834
A9: CUST0008 | B9: Eswari Raj | C9: Female | D9: 34376 | E9: 9633597839 | F9: eswari8@gmail.com | G9: Erode | H9: Tamil Nadu | I9: South | J9: Silver | K9: 43927
A10: CUST0009 | B10: Mani Nair | C10: Male | D10: 37648 | E10: 9408545686 | F10: mani9@gmail.com | G10: Chennai | H10: Tamil Nadu | I10: South | J10: Bronze | K10: 43977
A11: CUST0010 | B11: Tara Achari | C11: Female | D11: 33263 | E11: 9770629385 | F11: tara10@gmail.com | G11: Erode | H11: Tamil Nadu | I11: South | J11: Bronze | K11: 44026
A12: CUST0011 | B12: Prasath Mudaliar | C12: Male | D12: 39036 | E12: 9735509839 | F12: prasath11@gmail.com | G12: Chennai | H12: Tamil Nadu | I12: South | J12: Bronze | K12: 43489
A13: CUST0012 | B13: Meena Gupta | C13: Female | D13: 37491 | E13: 9558601461 | F13: meena12@gmail.com | G13: Chennai | H13: Tamil Nadu | I13: South | J13: Bronze | K13: 45047
... A293: CUST0292 | B293: Nirmala Venkataraman | C293: Female | D293: 25491 | E293: 9322664095 | F293: nirmala292@gmail.com | G293: Tiruppur | H293: Tamil Nadu | I293: South | J293: Silver | K293: 44136
A294: CUST0293 | B294: Suresh Chandran | C294: Male | D294: 35225 | E294: 9468999657 | F294: suresh293@gmail.com | G294: Mysuru | H294: Karnataka | J294: Gold | K294: 44662
A295: CUST0294 | B295: Deepak Venkataraman | C295: Male | D295: 20441 | E295: 9223139628 | F295: deepak294@gmail.com | G295: Salem | H295: Tamil Nadu | I295: South | J295: Silver | K295: 44127
A296: CUST0295 | B296: Latha Gounder | C296: Female | D296: 35302 | E296: 9595378308 | F296: latha295@gmail.com | G296: Madurai | H296: Tamil Nadu | I296: South | J296: Silver | K296: 45086
A297: CUST0296 | B297: Uma Pandian | C297: Female | D297: 34433 | E297: 9605504475 | F297: uma296@gmail.com | G297: Kochi | H297: Kerala | I297: South | J297: Bronze | K297: 43675
A298: CUST0297 | B298: Nithya Sharma | C298: Female | D298: 20681 | E298: 9207927292 | F298: nithya297@gmail.com | G298: Madurai | H298: Tamil Nadu | I298: South | J298: Gold | K298: 45587
A299: CUST0298 | B299: Divya Naicker | C299: Female | D299: 32897 | E299: 9183306581 | F299: divya298@gmail.com | G299: Chennai | H299: Tamil Nadu | I299: South | J299: Silver | K299: 43790
A300: CUST0299 | B300: Chandran Krishnan | C300: Male | D300: 25119 | E300: 9484492979 | F300: chandran299@gmail.com | G300: Coimbatore | H300: Tamil Nadu | I300: South | J300: Bronze | K300: 44905
A301: CUST0300 | B301: Indira Prabhu | C301: Female | D301: 37532 | E301: 9574656314 | F301: indira300@gmail.com | G301: Coimbatore | H301: Tamil Nadu | I301: South | J301: Bronze | K301: 43986
A302: CUST0301 | B302: Dinesh Chandran | C302: Male | D302: 23458 | E302: 9841254136 | F302: dinesh301@gmail.com | G302: Kochi | H302: Kerala | I302: South | J302: Bronze | K302: 44700
A303: CUST0302 | B303: Rajesh Reddy | C303: Male | D303: 21684 | E303: 9923682643 | F303: rajesh302@gmail.com | G303: Coimbatore | H303: Tamil Nadu | I303: South | J303: Bronze | K303: 44646
A304: CUST0303 | B304: Kamala Subramaniam | C304: Female | D304: 27906 | E304: 9198125433 | F304: kamala303@gmail.com | G304: Salem | H304: Tamil Nadu | I304: South | J304: Silver | K304: 43920
A305: CUST0304 | B305: Missing Customer Name | C305: Female | D305: 31136 | E305: 9830100976 | F305: yamuna304@gmail.com | G305: Coimbatore | H305: Tamil Nadu | I305: South | J305: Bronze | K305: 43888
A306: CUST0305 | B306: Hemalatha Mudaliar | C306: Female | D306: 23255 | E306: 9280262874 | F306: hemalatha305@gmail.com | G306: Salem | H306: Tamil Nadu | I306: South | J306: Bronze | K306: 45821
... A446: CUST0445 | B446: Anjali Kumar | C446: Female | D446: 20380 | E446: 9562572075 | F446: anjali445@gmail.com | G446: Madurai | H446: Tamil Nadu | I446: South | J446: Silver | K446: 43516
A447: CUST0446 | B447: Ramesh Sharma | C447: Male | D447: 25126 | E447: 9232975024 | F447: ramesh446@gmail.com | G447: Chennai | H447: Tamil Nadu | J447: Silver | K447: 44783
A448: CUST0447 | B448: Harini Krishnan | C448: Female | D448: 28286 | E448: 9605408862 | F448: harini447@gmail.com | G448: Pune | H448: Maharashtra | I448: West | J448: Bronze | K448: 44027
A449: CUST0448 | B449: Sanjay Achari | C449: Male | D449: 26059 | E449: 9971388578 | F449: sanjay448@gmail.com | G449: Erode | H449: Tamil Nadu | I449: South | J449: Silver | K449: 45298
A450: CUST0449 | B450: Sudha Sekar | C450: Female | D450: 34486 | E450: 9250188999 | F450: sudha449@gmail.com | G450: Mysuru | H450: Karnataka | I450: South | J450: Bronze | K450: 43763
A451: CUST0450 | B451: Bhavani Chettiar | C451: Female | D451: 26593 | E451: 9303546093 | F451: bhavani450@gmail.com | G451: Bengaluru | H451: Karnataka | I451: South | J451: Gold | K451: 43554
A452: CUST0451 | B452: Divya Nair | C452: Female | D452: 30943 | E452: 9272134233 | F452: divya451@gmail.com | G452: Madurai | H452: Tamil Nadu | I452: South | J452: Silver | K452: 43230
A453: CUST0452 | B453: Dhanya Varma | C453: Female | D453: 28799 | E453: 9552147658 | F453: dhanya452@gmail.com | G453: Mysuru | H453: Karnataka | I453: South | J453: Bronze | K453: 43587
A454: CUST0453 | B454: Prasath Nair | C454: Male | D454: 24265 | E454: 9906476640 | F454: prasath453@gmail.com | G454: Mysuru | H454: Karnataka | I454: South | J454: Bronze | K454: 44431
A455: CUST0454 | B455: Raghav Nair | C455: Male | D455: 32831 | E455: 9217824679 | F455: raghav454@gmail.com | G455: Bengaluru | H455: Karnataka | I455: South | J455: Silver | K455: 43639
A456: CUST0455 | B456: Nithya Venkataraman | C456: Female | D456: 36474 | E456: 9923973312 | F456: nithya455@gmail.com | G456: Pune | H456: Maharashtra | I456: West | J456: Gold | K456: 43156
A457: CUST0456 | B457: Kamala Devi | C457: Female | D457: 31301 | E457: 9741117091 | F457: kamala456@gmail.com | G457: Coimbatore | H457: Tamil Nadu | I457: South | J457: Bronze | K457: 44860
A458: CUST0457 | B458: Nithya Raj | C458: Female | D458: 29337 | E458: 9188707067 | F458: nithya457@gmail.com | G458: Bengaluru | H458: Karnataka | I458: South | J458: Silver | K458: 45091
...

Sheet Sheet1
A3: Sum of Sales_Amount | B3: Sum of Profit | C3: Sum of Quantity | D3: Count of Invoice_Number
A4: 2868432.6 | B4: 737358.89 | C4: 9823 | D4: 2500

Sheet Sheet3
A3: Row Labels | B3: Sum of Sales_Amount
A4: <10-03-2025
A5: <10-03-2025
A6: 2025 | B6: 2335789.5
A7: Mar | B7: 1682.32
A8: Apr | B8: 195249.44
A9: May | B9: 223829.24
A10: Jun | B10: 226577.54
A11: Jul | B11: 171047.56
A12: Aug | B12: 193434.23
A13: Sep | B13: 239642.24
A14: Oct | B14: 445171.86
A15: Nov | B15: 303499.88
A16: Dec | B16: 335655.2
A17: 2026 | B17: 532643.09
... A21: Grand Total | B21: 2868432.6
E28: monthly sales pivot table and chart

Sheet Sheet4
A3: Row Labels | B3: Sum of Sales_Amount
A4: Bakery | B4: 14322.38
A5: Frozen Foods | B5: 4311.67
A6: Fruits | B6: 29494.94
A7: Bakery | B7: 343694.76
A8: Beverages | B8: 471195.53
A9: Cleaning | B9: 97873.45
A10: Dairy | B10: 351546.11
A11: Frozen Foods | B11: 53359.36
A12: Fruits | B12: 206014.11
A13: Household | B13: 144591.68
A14: Masala | B14: 153158.06
A15: Missing Catogory | B15: 8137.18
... A20: Vegetables | B20: 218513.72
A21: (blank)
A22: Grand Total | B22: 2868432.6
I28: Category wise sales pivot table

Sheet Sheet5
A3: Row Labels | B3: Sum of Sales_Amount
A4: East | B4: 62655.19
A5: Missing Region | B5: 2665.21
A6: North | B6: 246937.59
A7: South | B7: 1869722.7
A8: West | B8: 686451.93
A9: (blank)
A10: Grand Total | B10: 2868432.6
H29: Sales by region

Sheet Sheet6
A3: Row Labels | B3: Sum of Sales_Amount
A4: In-Store | B4: 1969380.3
A5: Mobile App | B5: 286557.95
A6: Online | B6: 612494.35
A7: (blank)
A8: Grand Total | B8: 2868432.6
F28: Sales by channel

Sheet Sheet7
A3: Row Labels | B3: Sum of Sales_Amount
A4: Cash | B4: 432694.8
A5: Credit Card | B5: 468798.76
A6: Debit Card | B6: 490398.19
A7: Net Banking | B7: 438113.87
A8: UPI | B8: 549309.6
A9: Wallet | B9: 489117.38
A10: (blank)
A11: Grand Total | B11: 2868432.6
F28: Sales by Payment mode

Sheet Sheet8
A3: Row Labels | B3: Count of Invoice_Number
A4: Not Returned | B4: 2386
A5: Returned | B5: 114
A6: (blank)
A7: Grand Total | B7: 2500
H27: Return status transaction

Sheet Sales_Transactions
A1: Invoice_Number | B1: Transaction_Date | C1: Customer_ID | D1: Customer Name | E1: Membership | F1: Product_ID | G1: Product Name | H1: Catogory | I1: Store_ID | J1: Store Name | K1: Region | L1: Employee_ID | M1: Employee Name | N1: Department | O1: Quantity | P1: Unit_Price | Q1: Discount_Pct | R1: Discount_Amount | S1: Sales_Amount | T1: Cost_Amount | U1: Profit | V1: Payment_Mode | W1: Return_Status | X1: Sales_Channel | Y1: Order_Time | Z1: Day_Type
A2: INV100252 | B2: 45767 | C2: CUST0567 | D2: =_xlfn.XLOOKUP(Sales_Transactions!$C2,Customer!$A$2:$A$701,Customer!$B$2:$B$701,"Missing") -> Bharath Balan | E2: =_xlfn.XLOOKUP(Table14[[#This Row],[Customer_ID]],Table10[Customer_ID],Table10[Membership],"Missing Membership") -> Gold | F2: PRD018 | G2: =_xlfn.XLOOKUP(Sales_Transactions!$F2,Products!$A$2:$A$151,Products!$B$2:$B$151,"missing product") -> Aavin Cheese 200g | H2: =_xlfn.XLOOKUP(Sales_Transactions!$F2,Table9[Product_ID],Table9[Category],"Missing Catogory") -> Dairy | I2: STR046 | J2: =_xlfn.XLOOKUP(Sales_Transactions!$I2,Store!$A$2:$A$181,Store!$B$2:$B$181,"Missing Store") -> FreshMart Mysuru Colony | K2: =_xlfn.XLOOKUP(Sales_Transactions!$I2,Store!$A$2:$A$181,Store!$D$2:$D$181,"Missing Region") -> South | L2: EMP0191 | M2: Thenmozhi Krishnan | N2: =_xlfn.XLOOKUP(Sales_Transactions!$L2,Table12[Employee_ID],Table12[Department],"Missing Department") -> Billing | O2: 8 | P2: 238.51 | Q2: 0 | R2: 0 | S2: 2194.29 | T2: 1529.6 | U2: 664.69 | V2: Debit Card | W2: Returned | X2: Mobile App | Y2: 19:14 | Z2: Weekend
A3: INV100360 | B3: 45825 | C3: CUST0669 | D3: =_xlfn.XLOOKUP(Sales_Transactions!$C3,Customer!$A$2:$A$701,Customer!$B$2:$B$701,"Missing") -> Mani Krishnan | E3: =_xlfn.XLOOKUP(Table14[[#This Row],[Customer_ID]],Table10[Customer_ID],Table10[Membership],"Missing Membership") -> Silver | F3: PRD025 | G3: =_xlfn.XLOOKUP(Sales_Transactions!$F3,Products!$A$2:$A$151,Products!$B$2:$B$151,"missing product") -> Nescafe Soft Drinks Pack | H3: =_xlfn.XLOOKUP(Sales_Transactions!$F3,Table9[Product_ID],Table9[Category],"Missing Catogory") -> Beverages | I3: STR094 | J3: =_xlfn.XLOOKUP(Sales_Transactions!$I3,Store!$A$2:$A$181,Store!$B$2:$B$181,"Missing Store") -> FreshMart Mumbai Central | K3: =_xlfn.XLOOKUP(Sales_Transactions!$I3,Store!$A$2:$A$181,Store!$D$2:$D$181,"Missing Region") -> West | L3: EMP0347 | M3: Dhanush Chandran | N3: =_xlfn.XLOOKUP(Sales_Transactions!$L3,Table12[Employee_ID],Table12[Department],"Missing Department") -> Sales | O3: 4 | P3: 383.51 | Q3: 0 | R3: 0 | S3: 1534.04 | T3: 1143.6 | U3: 390.44 | V3: Debit Card | W3: Not Returned | X3: In-Store | Y3: 11:14 | Z3: Weekday
A4: INV101198 | B4: 46054 | C4: CUST0422 | D4: =_xlfn.XLOOKUP(Sales_Transactions!$C4,Customer!$A$2:$A$701,Customer!$B$2:$B$701,"Missing") -> Balamurugan Naidu | E4: =_xlfn.XLOOKUP(Table14[[#This Row],[Customer_ID]],Table10[Customer_ID],Table10[Membership],"Missing Membership") -> Silver | F4: PRD074 | G4: =_xlfn.XLOOKUP(Sales_Transactions!$F4,Products!$A$2:$A$151,Products!$B$2:$B$151,"missing product") -> Surf Excel Tissue Combo | H4: =_xlfn.XLOOKUP(Sales_Transactions!$F4,Table9[Product_ID],Table9[Category],"Missing Catogory") -> Household | I4: STR024 | J4: =_xlfn.XLOOKUP(Sales_Transactions!$I4,Store!$A$2:$A$181,Store!$B$2:$B$181,"Missing Store") -> FreshMart Bengaluru Plaza | K4: =_xlfn.XLOOKUP(Sales_Transactions!$I4,Store!$A$2:$A$181,Store!$D$2:$D$181,"Missing Region") -> South | L4: EMP0005 | M4: Harini Sekar | N4: =_xlfn.XLOOKUP(Sales_Transactions!$L4,Table12[Employee_ID],Table12[Department],"Missing Department") -> Inventory | O4: 1 | P4: 414.29 | Q4: 0 | R4: 0 | S4: 476.43 | T4: 314.26 | U4: 162.17 | V4: Debit Card | W4: Not Returned | X4: In-Store | Y4: 20:21 | Z4: Weekend
A5: INV101268 | B5: 45885 | C5: CUST0689 | D5: =_xlfn.XLOOKUP(Sales_Transactions!$C5,Customer!$A$2:$A$701,Customer!$B$2:$B$701,"Missing") -> Karthik Pillai | E5: =_xlfn.XLOOKUP(Table14[[#This Row],[Customer_ID]],Table10[Customer_ID],Table10[Membership],"Missing Membership") -> Silver | F5: PRD111 | G5: =_xlfn.XLOOKUP(Sales_Transactions!$F5,Products!$A$2:$A$151,Products!$B$2:$B$151,"missing product") -> Aachi Idli Rice 500g | H5: =_xlfn.XLOOKUP(Sales_Transactions!$F5,Table9[Product_ID],Table9[Category],"Missing Catogory") -> Rice | I5: STR154 | J5: =_xlfn.XLOOKUP(Sales_Transactions!$I5,Store!$A$2:$A$181,Store!$B$2:$B$181,"Missing Store") -> FreshMart Lucknow Heights | K5: =_xlfn.XLOOKUP(Sales_Transactions!$I5,Store!$A$2:$A$181,Store!$D$2:$D$181,"Missing Region") -> North | L5: EMP0182 | M5: Arun Naicker | N5: =_xlfn.XLOOKUP(Sales_Transactions!$L5,Table12[Employee_ID],Table12[Department],"Missing Department") -> Operations | O5: 5 | P5: 225.45 | Q5: 0 | R5: 0 | S5: 1296.34 | T5: 954.5 | U5: 341.84 | V5: Debit Card | W5: Not Returned | X5: Mobile App | Y5: 20:32 | Z5: Weekend
A6: INV100071 | B6: 45918 | C6: CUST0475 | D6: =_xlfn.XLOOKUP(Sales_Transactions!$C6,Customer!$A$2:$A$701,Customer!$B$2:$B$701,"Missing") -> Gopal Prabhu | E6: =_xlfn.XLOOKUP(Table14[[#This Row],[Customer_ID]],Table10[Customer_ID],Table10[Membership],"Missing Membership") -> Gold | F6: PRD093 | G6: =_xlfn.XLOOKUP(Sales_Transactions!$F6,Products!$A$2:$A$151,Products!$B$2:$B$151,"missing product") -> Local Farm Fresh Vegetables 250ml | H6: =_xlfn.XLOOKUP(Sales_Transactions!$F6,Table9[Product_ID],Table9[Category],"Missing Catogory") -> Vegetables | I6: STR076 | J6: =_xlfn.XLOOKUP(Sales_Transactions!$I6,Store!$A$2:$A$181,Store!$B$2:$B$181,"Missing Store") -> FreshMart Hyderabad Towers | K6: =_xlfn.XLOOKUP(Sales_Transactions!$I6,Store!$A$2:$A$181,Store!$D$2:$D$181,"Missing Region") -> South | L6: EMP0099 | M6: Elango Nair | N6: =_xlfn.XLOOKUP(Sales_Transactions!$L6,Table12[Employee_ID],Table12[Department],"Missing Department") -> Cashier | O6: 3 | P6: 97.24 | Q6: 0 | R6: 0 | S6: 291.72 | T6: 239.46 | U6: 52.26 | V6: Net Banking | W6: Not Returned | X6: In-Store | Y6: 16:02 | Z6: Weekday
A7: INV100478 | B7: 46011 | C7: CUST0485 | D7: =_xlfn.XLOOKUP(Sales_Transactions!$C7,Customer!$A$2:$A$701,Customer!$B$2:$B$701,"Missing") -> Dhanush Venkataraman | E7: =_xlfn.XLOOKUP(Table14[[#This Row],[Customer_ID]],Table10[Customer_ID],Table10[Membership],"Missing Membership") -> Gold | F7: PRD057 | G7: =_xlfn.XLOOKUP(Sales_Transactions!$F7,Products!$A$2:$A$151,Products!$B$2:$B$151,"missing product") -> Parle Chocolates 500g | H7: =_xlfn.XLOOKUP(Sales_Transactions!$F7,Table9[Product_ID],Table9[Category],"Missing Catogory") -> Snacks | I7: STR071 | J7: =_xlfn.XLOOKUP(Sales_Transactions!$I7,Store!$A$2:$A$181,Store!$B$2:$B$181,"Missing Store") -> FreshMart Salem Crossing | K7: =_xlfn.XLOOKUP(Sales_Transactions!$I7,Store!$A$2:$A$181,Store!$D$2:$D$181,"Missing Region") -> South | L7: EMP0144 | M7: Chitra Nair | N7: =_xlfn.XLOOKUP(Sales_Transactions!$L7,Table12[Employee_ID],Table12[Department],"Missing Department") -> Cashier | O7: 8 | P7: 323.91 | Q7: 0 | R7: 0 | S7: 2979.97 | T7: 1880.4 | U7: 1099.57 | V7: Wallet | W7: Not Returned | X7: In-Store | Y7: 09:38 | Z7: Weekend
A8: INV101553 | B8: 45984 | C8: CUST0143 | D8: =_xlfn.XLOOKUP(Sales_Transactions!$C8,Customer!$A$2:$A$701,Customer!$B$2:$B$701,"Missing") -> Charulatha Iyer | E8: =_xlfn.XLOOKUP(Table14[[#This Row],[Customer_ID]],Table10[Customer_ID],Table10[Membership],"Missing Membership") -> Silver | F8: PRD070 | G8: =_xlfn.XLOOKUP(Sales_Transactions!$F8,Products!$A$2:$A$151,Products!$B$2:$B$151,"missing product") -> Surf Excel Batteries 2kg | H8: =_xlfn.XLOOKUP(Sales_Transactions!$F8,Table9[Product_ID],Table9[Category],"Missing Catogory") -> Household | I8: STR128 | J8: =_xlfn.XLOOKUP(Sales_Transactions!$I8,Store!$A$2:$A$181,Store!$B$2:$B$181,"Missing Store") -> FreshMart Surat Junction | K8: =_xlfn.XLOOKUP(Sales_Transactions!$I8,Store!$A$2:$A$181,Store!$D$2:$D$181,"Missing Region") -> West | L8: EMP0177 | M8: Raghav Iyer | N8: =_xlfn.XLOOKUP(Sales_Transactions!$L8,Table12[Employee_ID],Table12[Department],"Missing Department") -> Store Manager | O8: 2 | P8: 233.47 | Q8: 15 | R8: 70.04 | S8: 456.43 | T8: 377.96 | U8: 78.47 | V8: Wallet | W8: Not Returned | X8: Mobile App | Y8: 21:04 | Z8: Weekend
A9: INV101964 | B9: 45991 | C9: CUST0427 | D9: =_xlfn.XLOOKUP(Sales_Transactions!$C9,Customer!$A$2:$A$701,Customer!$B$2:$B$701,"Missing") -> Ashok Gounder | E9: =_xlfn.XLOOKUP(Table14[[#This Row],[Customer_ID]],Table10[Customer_ID],Table10[Membership],"Missing Membership") -> Bronze | F9: PRD097 | G9: =_xlfn.XLOOKUP(Sales_Transactions!$F9,Products!$A$2:$A$151,Products!$B$2:$B$151,"missing product") -> Local Farm Fresh Vegetables 250ml v2 | H9: =_xlfn.XLOOKUP(Sales_Transactions!$F9,Table9[Product_ID],Table9[Category],"Missing Catogory") -> Vegetables | I9: STR062 | J9: =_xlfn.XLOOKUP(Sales_Transactions!$I9,Store!$A$2:$A$181,Store!$B$2:$B$181,"Missing Store") -> FreshMart Hyderabad Crossing | K9: =_xlfn.XLOOKUP(Sales_Transactions!$I9,Store!$A$2:$A$181,Store!$D$2:$D$181,"Missing Region") -> South | L9: EMP0350 | M9: Uma Pandian | N9: =_xlfn.XLOOKUP(Sales_Transactions!$L9,Table12[Employee_ID],Table12[Department],"Missing Department") -> Cashier | O9: 4 | P9: 365.92 | Q9: 15 | R9: 219.55 | S9: 1430.75 | T9: 1241.52 | U9: 189.23 | V9: Wallet | W9: Not Returned | X9: In-Store | Y9: 19:16 | Z9: Weekend
A10: INV100003 | B10: 45920 | C10: CUST0438 | D10: =_xlfn.XLOOKUP(Sales_Transactions!$C10,Customer!$A$2:$A$701,Customer!$B$2:$B$701,"Missing") -> Nandhini Mudaliar | E10: =_xlfn.XLOOKUP(Table14[[#This Row],[Customer_ID]],Table10[Customer_ID],Table10[Membership],"Missing Membership") -> Bronze | F10: PRD119 | G10: =_xlfn.XLOOKUP(Sales_Transactions!$F10,Products!$A$2:$A$151,Products!$B$2:$B$151,"missing product") -> Gold Winner Sunflower Oil 200g | H10: =_xlfn.XLOOKUP(Sales_Transactions!$F10,Table9[Product_ID],Table9[Category],"Missing Catogory") -> Oil | I10: STR008 | J10: =_xlfn.XLOOKUP(Sales_Transactions!$I10,Store!$A$2:$A$181,Store!$B$2:$B$181,"Missing Store") -> FreshMart Kochi Plaza | K10: =_xlfn.XLOOKUP(Sales_Transactions!$I10,Store!$A$2:$A$181,Store!$D$2:$D$181,"Missing Region") -> South | L10: EMP0249 | M10: Radha Murugan | N10: =_xlfn.XLOOKUP(Sales_Transactions!$L10,Table12[Employee_ID],Table12[Department],"Missing Department") -> Inventory | O10: 1 | P10: 234.86 | Q10: 10 | R10: 23.49 | S10: 243.08 | T10: 213.23 | U10: 29.85 | V10: Cash | W10: Not Returned | X10: In-Store | Y10: 09:53 | Z10: Weekend
A11: INV100008 | B11: 46110 | C11: CUST0267 | D11: =_xlfn.XLOOKUP(Sales_Transactions!$C11,Customer!$A$2:$A$701,Customer!$B$2:$B$701,"Missing") -> Manoj Gounder | E11: =_xlfn.XLOOKUP(Table14[[#This Row],[Customer_ID]],Table10[Customer_ID],Table10[Membership],"Missing Membership") -> Silver | F11: PRD030 | G11: =_xlfn.XLOOKUP(Sales_Transactions!$F11,Products!$A$2:$A$151,Products!$B$2:$B$151,"missing product") -> Nescafe Tea Combo | H11: =_xlfn.XLOOKUP(Sales_Transactions!$F11,Table9[Product_ID],Table9[Category],"Missing Catogory") -> Beverages | I11: STR019 | J11: =_xlfn.XLOOKUP(Sales_Transactions!$I11,Store!$A$2:$A$181,Store!$B$2:$B$181,"Missing Store") -> FreshMart Hyderabad Heights | K11: =_xlfn.XLOOKUP(Sales_Transactions!$I11,Store!$A$2:$A$181,Store!$D$2:$D$181,"Missing Region") -> South | L11: EMP0273 | M11: Prasath Subramaniam | N11: =_xlfn.XLOOKUP(Sales_Transactions!$L11,Table12[Employee_ID],Table12[Department],"Missing Department") -> Store Manager | O11: 4 | P11: 172.63 | Q11: 0 | R11: 0 | S11: 794.1 | T11: 568 | U11: 226.1 | V11: Cash | W11: Not Returned | X11: In-Store | Y11: 17:13 | Z11: Weekend
A12: INV100017 | B12: 45792 | C12: CUST0680 | D12: =_xlfn.XLOOKUP(Sales_Transactions!$C12,Customer!$A$2:$A$701,Customer!$B$2:$B$701,"Missing") -> Lokesh Chandran | E12: =_xlfn.XLOOKUP(Table14[[#This Row],[Customer_ID]],Table10[Customer_ID],Table10[Membership],"Missing Membership") -> Silver | F12: PRD022 | G12: =_xlfn.XLOOKUP(Sales_Transactions!$F12,Products!$A$2:$A$151,Products!$B$2:$B$151,"missing product") -> Aavin Milk Pack | H12: =_xlfn.XLOOKUP(Sales_Transactions!$F12,Table9[Product_ID],Table9[Category],"Missing Catogory") -> Dairy | I12: STR075 | J12: =_xlfn.XLOOKUP(Sales_Transactions!$I12,Store!$A$2:$A$181,Store!$B$2:$B$181,"Missing Store") -> FreshMart Salem Main Road | K12: =_xlfn.XLOOKUP(Sales_Transactions!$I12,Store!$A$2:$A$181,Store!$D$2:$D$181,"Missing Region") -> South | L12: EMP0300 | M12: Thiru Raj | N12: =_xlfn.XLOOKUP(Sales_Transactions!$L12,Table12[Employee_ID],Table12[Department],"Missing Department") -> Sales | O12: 4 | P12: 397.22 | Q12: 20 | R12: 317.78 | S12: 1271.1 | T12: 1277.48 | U12: -6.38 | V12: Cash | W12: Not Returned | X12: In-Store | Y12: 17:19 | Z12: Weekday
A13: INV100021 | B13: 45803 | C13: CUST0589 | D13: =_xlfn.XLOOKUP(Sales_Transactions!$C13,Customer!$A$2:$A$701,Customer!$B$2:$B$701,"Missing") -> Ovi Venkataraman | E13: =_xlfn.XLOOKUP(Table14[[#This Row],[Customer_ID]],Table10[Customer_ID],Table10[Membership],"Missing Membership") -> Silver | F13: PRD029 | G13: =_xlfn.XLOOKUP(Sales_Transactions!$F13,Products!$A$2:$A$151,Products!$B$2:$B$151,"missing product") -> Pepsi Tea 200g | H13: =_xlfn.XLOOKUP(Sales_Transactions!$F13,Table9[Product_ID],Table9[Category],"Missing Catogory") -> Beverages | I13: STR053 | J13: =_xlfn.XLOOKUP(Sales_Transactions!$I13,Store!$A$2:$A$181,Store!$B$2:$B$181,"Missing Store") -> FreshMart Tiruppur Heights | K13: =_xlfn.XLOOKUP(Sales_Transactions!$I13,Store!$A$2:$A$181,Store!$D$2:$D$181,"Missing Region") -> South | L13: EMP0007 | M13: Udhay Selvam | N13: =_xlfn.XLOOKUP(Sales_Transactions!$L13,Table12[Employee_ID],Table12[Department],"Missing Department") -> Billing | O13: 5 | P13: 332.73 | Q13: 15 | R13: 249.55 | S13: 1414.1 | T13: 1306.1 | U13: 108 | V13: Cash | W13: Not Returned | X13: In-Store | Y13: 15:38 | Z13: Weekday
... A256: INV101632 | B256: 45914 | C256: CUST0060 | D256: =_xlfn.XLOOKUP(Sales_Transactions!$C256,Customer!$A$2:$A$701,Customer!$B$2:$B$701,"Missing") -> Anand Subramaniam | E256: =_xlfn.XLOOKUP(Table14[[#This Row],[Customer_ID]],Table10[Customer_ID],Table10[Membership],"Missing Membership") -> Gold | F256: PRD046 | G256: =_xlfn.XLOOKUP(Sales_Transactions!$F256,Products!$A$2:$A$151,Products!$B$2:$B$151,"missing product") -> ITC Ice Cream 250ml | H256: =_xlfn.XLOOKUP(Sales_Transactions!$F256,Table9[Product_ID],Table9[Category],"Missing Catogory") -> Frozen Foods | I256: STR033 | J256: =_xlfn.XLOOKUP(Sales_Transactions!$I256,Store!$A$2:$A$181,Store!$B$2:$B$181,"Missing Store") -> FreshMart Ahmedabad Complex | K256: =_xlfn.XLOOKUP(Sales_Transactions!$I256,Store!$A$2:$A$181,Store!$D$2:$D$181,"Missing Region") -> South | L256: EMP0113 | M256: Radha Rao | N256: =_xlfn.XLOOKUP(Sales_Transactions!$L256,Table12[Employee_ID],Table12[Department],"Missing Department") -> Inventory | O256: 7 | P256: 58.27 | Q256: 10 | R256: 40.79 | S256: 422.17 | T256: 339.01 | U256: 83.16 | V256: Cash | W256: Not Returned | X256: In-Store | Y256: 15:45 | Z256: Weekend
A257: INV101634 | B257: 45942 | C257: CUST0353 | D257: =_xlfn.XLOOKUP(Sales_Transactions!$C257,Customer!$A$2:$A$701,Customer!$B$2:$B$701,"Missing") -> Mala Nair | E257: =_xlfn.XLOOKUP(Table14[[#This Row],[Customer_ID]],Table10[Customer_ID],Table10[Membership],"Missing Membership") -> Gold | F257: PRD001 | G257: =_xlfn.XLOOKUP(Sales_Transactions!$F257,Products!$A$2:$A$151,Products!$B$2:$B$151,"missing product") -> Local Bakers Buns 1kg | H257: =_xlfn.XLOOKUP(Sales_Transactions!$F257,Table9[Product_ID],Table9[Category],"Missing Catogory") -> Bakery | I257: STR145 | J257: =_xlfn.XLOOKUP(Sales_Transactions!$I257,Store!$A$2:$A$181,Store!$B$2:$B$181,"Missing Store") -> FreshMart Lucknow Main Road | K257: =_xlfn.XLOOKUP(Sales_Transactions!$I257,Store!$A$2:$A$181,Store!$D$2:$D$181,"Missing Region") -> North | L257: EMP0117 | M257: Janani Krishnan | N257: =_xlfn.XLOOKUP(Sales_Transactions!$L257,Table12[Employee_ID],Table12[Department],"Missing Department") -> Billing | O257: 5 | P257: 340.64 | Q257: 0 | R257: 0 | S257: Rs.1958.68 | T257: 923.7 | U257: 1034.98 | V257: Cash | W257: Not Returned | X257: In-Store | Y257: 13:37 | Z257: Weekend
A258: INV101636 | B258: 45886 | C258: CUST0156 | D258: =_xlfn.XLOOKUP(Sales_Transactions!$C258,Customer!$A$2:$A$701,Customer!$B$2:$B$701,"Missing") -> Tara Chettiar | E258: =_xlfn.XLOOKUP(Table14[[#This Row],[Customer_ID]],Table10[Customer_ID],Table10[Membership],"Missing Membership") -> Gold | F258: PRD142 | G258: =_xlfn.XLOOKUP(Sales_Transactions!$F258,Products!$A$2:$A$151,Products!$B$2:$B$151,"missing product") -> Lizol Dishwash 200g | H258: =_xlfn.XLOOKUP(Sales_Transactions!$F258,Table9[Product_ID],Table9[Category],"Missing Catogory") -> Cleaning | I258: STR022 | J258: =_xlfn.XLOOKUP(Sales_Transactions!$I258,Store!$A$2:$A$181,Store!$B$2:$B$181,"Missing Store") -> FreshMart Tiruppur Complex | K258: =_xlfn.XLOOKUP(Sales_Transactions!$I258,Store!$A$2:$A$181,Store!$D$2:$D$181,"Missing Region") -> South | L258: EMP0284 | M258: Naveen Venkataraman | N258: =_xlfn.XLOOKUP(Sales_Transactions!$L258,Table12[Employee_ID],Table12[Department],"Missing Department") -> Sales | O258: 3 | P258: 568.76 | Q258: 0 | R258: 0 | S258: 1962.22 | T258: 1187.61 | U258: 774.61 | V258: Cash | W258: Not Returned | X258: In-Store | Y258: 09:41 | Z258: Weekend
A259: INV101643 | B259: 45952 | C259: CUST0534 | D259: =_xlfn.XLOOKUP(Sales_Transactions!$C259,Customer!$A$2:$A$701,Customer!$B$2:$B$701,"Missing") -> Kalpana Nair | E259: =_xlfn.XLOOKUP(Table14[[#This Row],[Customer_ID]],Table10[Customer_ID],Table10[Membership],"Missing Membership") -> Silver | F259: PRD025 | G259: =_xlfn.XLOOKUP(Sales_Transactions!$F259,Products!$A$2:$A$151,Products!$B$2:$B$151,"missing product") -> Nescafe Soft Drinks Pack | H259: =_xlfn.XLOOKUP(Sales_Transactions!$F259,Table9[Product_ID],Table9[Category],"Missing Catogory") -> Beverages | I259: STR064 | J259: =_xlfn.XLOOKUP(Sales_Transactions!$I259,Store!$A$2:$A$181,Store!$B$2:$B$181,"Missing Store") -> FreshMart Kochi Extension | K259: =_xlfn.XLOOKUP(Sales_Transactions!$I259,Store!$A$2:$A$181,Store!$D$2:$D$181,"Missing Region") -> South | L259: EMP0234 | M259: Lalitha Menon | N259: =_xlfn.XLOOKUP(Sales_Transactions!$L259,Table12[Employee_ID],Table12[Department],"Missing Department") -> Sales | O259: 5 | P259: 383.51 | Q259: 0 | R259: 0 | S259: 1917.55 | T259: 1429.5 | U259: 488.05 | V259: Cash | W259: Not Returned | X259: Online | Y259: 18:26 | Z259: Weekday
A260: INV101657 | B260: 45834 | C260: CUST0346 | D260: =_xlfn.XLOOKUP(Sales_Transactions!$C260,Customer!$A$2:$A$701,Customer!$B$2:$B$701,"Missing") -> Thenmozhi Devi | E260: =_xlfn.XLOOKUP(Table14[[#This Row],[Customer_ID]],Table10[Customer_ID],Table10[Membership],"Missing Membership") -> Gold | F260: PRD051 | G260: =_xlfn.XLOOKUP(Sales_Transactions!$F260,Products!$A$2:$A$151,Products!$B$2:$B$151,"missing product") -> Cadbury Biscuits 250ml | H260: =_xlfn.XLOOKUP(Sales_Transactions!$F260,Table9[Product_ID],Table9[Category],"Missing Catogory") -> Snacks | I260: STR160 | J260: =_xlfn.XLOOKUP(Sales_Transactions!$I260,Store!$A$2:$A$181,Store!$B$2:$B$181,"Missing Store") -> FreshMart Lucknow Complex | K260: =_xlfn.XLOOKUP(Sales_Transactions!$I260,Store!$A$2:$A$181,Store!$D$2:$D$181,"Missing Region") -> North | L260: EMP0073 | M260: Harini Prabhu | N260: =_xlfn.XLOOKUP(Sales_Transactions!$L260,Table12[Employee_ID],Table12[Department],"Missing Department") -> Sales | O260: 6 | P260: 158.31 | Q260: 5 | R260: 47.49 | S260: 902.37 | T260: 676.8 | U260: 225.57 | V260: Cash | W260: Not Returned | X260: In-Store | Y260: 12:20 | Z260: Weekday
A261: INV101673 | B261: 45888 | C261: CUST0409 | D261: =_xlfn.XLOOKUP(Sales_Transactions!$C261,Customer!$A$2:$A$701,Customer!$B$2:$B$701,"Missing") -> Banu Subramaniam | E261: =_xlfn.XLOOKUP(Table14[[#This Row],[Customer_ID]],Table10[Customer_ID],Table10[Membership],"Missing Membership") -> Gold | F261: PRD032 | G261: =_xlfn.XLOOKUP(Sales_Transactions!$F261,Products!$A$2:$A$151,Products!$B$2:$B$151,"missing product") -> Coca-Cola Coffee Combo | H261: =_xlfn.XLOOKUP(Sales_Transactions!$F261,Table9[Product_ID],Table9[Category],"Missing Catogory") -> Beverages | I261: STR006 | J261: =_xlfn.XLOOKUP(Sales_Transactions!$I261,Store!$A$2:$A$181,Store!$B$2:$B$181,"Missing Store") -> FreshMart Mysuru Junction | K261: =_xlfn.XLOOKUP(Sales_Transactions!$I261,Store!$A$2:$A$181,Store!$D$2:$D$181,"Missing Region") -> South | L261: EMP0265 | M261: Padma Subramaniam | N261: =_xlfn.XLOOKUP(Sales_Transactions!$L261,Table12[Employee_ID],Table12[Department],"Missing Department") -> Operations | O261: 8 | P261: 154.01 | Q261: 0 | R261: 0 | S261: 1232.08 | T261: 927.28 | U261: 304.8 | V261: Cash | W261: Not Returned | X261: In-Store | Y261: 16:05 | Z261: Weekday
A262: INV101688 | B262: 45788 | C262: CUST0239 | D262: =_xlfn.XLOOKUP(Sales_Transactions!$C262,Customer!$A$2:$A$701,Customer!$B$2:$B$701,"Missing") -> Jayakumar Velan | E262: =_xlfn.XLOOKUP(Table14[[#This Row],[Customer_ID]],Table10[Customer_ID],Table10[Membership],"Missing Membership") -> Silver | F262: PRD060 | G262: =_xlfn.XLOOKUP(Sales_Transactions!$F262,Products!$A$2:$A$151,Products!$B$2:$B$151,"missing product") -> Himalaya Soap 250ml | H262: =_xlfn.XLOOKUP(Sales_Transactions!$F262,Table9[Product_ID],Table9[Category],"Missing Catogory") -> Personal Care | I262: STR149 | J262: =_xlfn.XLOOKUP(Sales_Transactions!$I262,Store!$A$2:$A$181,Store!$B$2:$B$181,"Missing Store") -> FreshMart Jaipur Point | K262: =_xlfn.XLOOKUP(Sales_Transactions!$I262,Store!$A$2:$A$181,Store!$D$2:$D$181,"Missing Region") -> North | L262: EMP0246 | M262: Padma Chettiar | N262: =_xlfn.XLOOKUP(Sales_Transactions!$L262,Table12[Employee_ID],Table12[Department],"Missing Department") -> Sales | O262: 1 | P262: 72.93 | Q262: 0 | R262: 0 | S262: 83.87 | T262: 54.25 | U262: 29.62 | V262: Cash | W262: Not Returned | X262: In-Store | Y262: 09:03 | Z262: Weekend
A263: INV101689 | B263: 45824 | C263: CUST0346 | D263: =_xlfn.XLOOKUP(Sales_Transactions!$C263,Customer!$A$2:$A$701,Customer!$B$2:$B$701,"Missing") -> Thenmozhi Devi | E263: =_xlfn.XLOOKUP(Table14[[#This Row],[Customer_ID]],Table10[Customer_ID],Table10[Membership],"Missing Membership") -> Gold | F263: PRD006 | G263: =_xlfn.XLOOKUP(Sales_Transactions!$F263,Products!$A$2:$A$151,Products!$B$2:$B$151,"missing product") -> Harvest Gold Cookies 500g | H263: =_xlfn.XLOOKUP(Sales_Transactions!$F263,Table9[Product_ID],Table9[Category],"Missing Catogory") -> Bakery | I263: STR106 | J263: =_xlfn.XLOOKUP(Sales_Transactions!$I263,Store!$A$2:$A$181,Store!$B$2:$B$181,"Missing Store") -> FreshMart Ahmedabad Crossing | K263: =_xlfn.XLOOKUP(Sales_Transactions!$I263,Store!$A$2:$A$181,Store!$D$2:$D$181,"Missing Region") -> West | L263: EMP0347 | M263: Dhanush Chandran | N263: =_xlfn.XLOOKUP(Sales_Transactions!$L263,Table12[Employee_ID],Table12[Department],"Missing Department") -> Sales | O263: 5 | P263: 345.01 | Q263: 0 | R263: 0 | S263: 1725.05 | T263: 1081.6 | U263: 643.45 | V263: Cash | W263: Not Returned | X263: In-Store | Y263: 19:18 | Z263: Weekday
A264: INV101690 | B264: 45923 | C264: CUST0011 | D264: =_xlfn.XLOOKUP(Sales_Transactions!$C264,Customer!$A$2:$A$701,Customer!$B$2:$B$701,"Missing") -> Prasath Mudaliar | E264: =_xlfn.XLOOKUP(Table14[[#This Row],[Customer_ID]],Table10[Customer_ID],Table10[Membership],"Missing Membership") -> Bronze | F264: PRD131 | G264: =_xlfn.XLOOKUP(Sales_Transactions!$F264,Products!$A$2:$A$151,Products!$B$2:$B$151,"missing product") -> Sakthi Powdered Spices 250ml | H264: =_xlfn.XLOOKUP(Sales_Transactions!$F264,Table9[Product_ID],Table9[Category],"Missing Catogory") -> Masala | I264: STR046 | J264: =_xlfn.XLOOKUP(Sales_Transactions!$I264,Store!$A$2:$A$181,Store!$B$2:$B$181,"Missing Store") -> FreshMart Mysuru Colony | K264: =_xlfn.XLOOKUP(Sales_Transactions!$I264,Store!$A$2:$A$181,Store!$D$2:$D$181,"Missing Region") -> South | L264: EMP0087 | M264: Nagarajan Rao | N264: =_xlfn.XLOOKUP(Sales_Transactions!$L264,Table12[Employee_ID],Table12[Department],"Missing Department") -> Sales | O264: 2 | P264: 93.47 | Q264: 0 | R264: 0 | S264: 186.94 | T264: 144.58 | U264: 42.36 | V264: Cash | W264: Returned | X264: In-Store | Y264: 18:57 | Z264: Weekday
A265: INV101709 | B265: 46059 | C265: CUST0399 | D265: =_xlfn.XLOOKUP(Sales_Transactions!$C265,Customer!$A$2:$A$701,Customer!$B$2:$B$701,"Missing") -> Karthik Kumar | E265: =_xlfn.XLOOKUP(Table14[[#This Row],[Customer_ID]],Table10[Customer_ID],Table10[Membership],"Missing Membership") -> Silver | F265: PRD082 | G265: =_xlfn.XLOOKUP(Sales_Transactions!$F265,Products!$A$2:$A$151,Products!$B$2:$B$151,"missing product") -> Organic Fresh Fresh Fruits Pack | H265: =_xlfn.XLOOKUP(Sales_Transactions!$F265,Table9[Product_ID],Table9[Category],"Missing Catogory") -> Fruits | I265: STR145 | J265: =_xlfn.XLOOKUP(Sales_Transactions!$I265,Store!$A$2:$A$181,Store!$B$2:$B$181,"Missing Store") -> FreshMart Lucknow Main Road | K265: =_xlfn.XLOOKUP(Sales_Transactions!$I265,Store!$A$2:$A$181,Store!$D$2:$D$181,"Missing Region") -> North | L265: EMP0002 | M265: Lokesh Gounder | N265: =_xlfn.XLOOKUP(Sales_Transactions!$L265,Table12[Employee_ID],Table12[Department],"Missing Department") -> Billing | O265: 3 | P265: 232.92 | Q265: 15 | R265: 104.81 | S265: 593.95 | T265: 577.23 | U265: 16.72 | V265: Cash | W265: Not Returned | X265: In-Store | Y265: 13:24 | Z265: Weekday
A266: INV101713 | B266: 45895 | C266: CUST0495 | D266: =_xlfn.XLOOKUP(Sales_Transactions!$C266,Customer!$A$2:$A$701,Customer!$B$2:$B$701,"Missing") -> Bhuvana Pillai | E266: =_xlfn.XLOOKUP(Table14[[#This Row],[Customer_ID]],Table10[Customer_ID],Table10[Membership],"Missing Membership") -> Gold | F266: PRD012 | G266: =_xlfn.XLOOKUP(Sales_Transactions!$F266,Products!$A$2:$A$151,Products!$B$2:$B$151,"missing product") -> Harvest Gold Rusk 1kg | H266: =_xlfn.XLOOKUP(Sales_Transactions!$F266,Table9[Product_ID],Table9[Category],"Missing Catogory") -> Bakery | I266: STR083 | J266: =_xlfn.XLOOKUP(Sales_Transactions!$I266,Store!$A$2:$A$181,Store!$B$2:$B$181,"Missing Store") -> FreshMart Salem Colony | K266: =_xlfn.XLOOKUP(Sales_Transactions!$I266,Store!$A$2:$A$181,Store!$D$2:$D$181,"Missing Region") -> South | L266: EMP0074 | M266: Indira Varma | N266: =_xlfn.XLOOKUP(Sales_Transactions!$L266,Table12[Employee_ID],Table12[Department],"Missing Department") -> Sales | O266: 8 | P266: 599.45 | Q266: 5 | R266: 239.78 | S266: Rs.4555.82 | T266: 2691.2 | U266: 1864.62 | V266: Cash | W266: Not Returned | X266: In-Store | Y266: 11:18 | Z266: Weekday
A267: INV101725 | B267: 45759 | C267: CUST0324 | D267: =_xlfn.XLOOKUP(Sales_Transactions!$C267,Customer!$A$2:$A$701,Customer!$B$2:$B$701,"Missing") -> Tamil Velan | E267: =_xlfn.XLOOKUP(Table14[[#This Row],[Customer_ID]],Table10[Customer_ID],Table10[Membership],"Missing Membership") -> Gold | F267: PRD006 | G267: =_xlfn.XLOOKUP(Sales_Transactions!$F267,Products!$A$2:$A$151,Products!$B$2:$B$151,"missing product") -> Harvest Gold Cookies 500g | H267: =_xlfn.XLOOKUP(Sales_Transactions!$F267,Table9[Product_ID],Table9[Category],"Missing Catogory") -> Bakery | I267: STR003 | J267: =_xlfn.XLOOKUP(Sales_Transactions!$I267,Store!$A$2:$A$181,Store!$B$2:$B$181,"Missing Store") -> FreshMart Tiruppur Square | K267: =_xlfn.XLOOKUP(Sales_Transactions!$I267,Store!$A$2:$A$181,Store!$D$2:$D$181,"Missing Region") -> South | L267: EMP0298 | M267: Balaji Reddy | N267: =_xlfn.XLOOKUP(Sales_Transactions!$L267,Table12[Employee_ID],Table12[Department],"Missing Department") -> Billing | O267: 8 | P267: 373.66 | Q267: 0 | R267: 0 | S267: 3437.67 | T267: 1730.56 | U267: 1707.11 | V267: Cash | W267: Not Returned | X267: Online | Y267: 12:47 | Z267: Weekend
A268: INV101732 | B268: 46040 | C268: CUST0569 | D268: =_xlfn.XLOOKUP(Sales_Transactions!$C268,Customer!$A$2:$A$701,Customer!$B$2:$B$701,"Missing") -> Sathish Krishnan | E268: =_xlfn.XLOOKUP(Table14[[#This Row],[Customer_ID]],Table10[Customer_ID],Table10[Membership],"Missing Membership") -> Bronze | F268: PRD024 | G268: =_xlfn.XLOOKUP(Sales_Transactions!$F268,Products!$A$2:$A$151,Products!$B$2:$B$151,"missing product") -> Aavin Milk Pack v2 | H268: =_xlfn.XLOOKUP(Sales_Transactions!$F268,Table9[Product_ID],Table9[Category],"Missing Catogory") -> Dairy | I268: STR151 | J268: =_xlfn.XLOOKUP(Sales_Transactions!$I268,Store!$A$2:$A$181,Store!$B$2:$B$181,"Missing Store") -> FreshMart Chandigarh Square | K268: =_xlfn.XLOOKUP(Sales_Transactions!$I268,Store!$A$2:$A$181,Store!$D$2:$D$181,"Missing Region") -> North | L268: EMP0277 | M268: Arun Velan | N268: =_xlfn.XLOOKUP(Sales_Transactions!$L268,Table12[Employee_ID],Table12[Department],"Missing Department") -> Cashier | O268: 3 | P268: 313.47 | Q268: 0 | R268: 0 | S268: 1081.47 | T268: 738.36 | U268: 343.11 | V268: Cash | W268: Not Returned | X268: Mobile App | Y268: 09:14 | Z268: Weekend
A269: INV101739 | B269: 46087 | C269: CUST0324 | D269: =_xlfn.XLOOKUP(Sales_Transactions!$C269,Customer!$A$2:$A$701,Customer!$B$2:$B$701,"Missing") -> Tamil Velan | E269: =_xlfn.XLOOKUP(Table14[[#This Row],[Customer_ID]],Table10[Customer_ID],Table10[Membership],"Missing Membership") -> Gold | F269: PRD082 | G269: =_xlfn.XLOOKUP(Sales_Transactions!$F269,Products!$A$2:$A$151,Products!$B$2:$B$151,"missing product") -> Organic Fresh Fresh Fruits Pack | H269: =_xlfn.XLOOKUP(Sales_Transactions!$F269,Table9[Product_ID],Table9[Category],"Missing Catogory") -> Fruits | I269: STR054 | J269: =_xlfn.XLOOKUP(Sales_Transactions!$I269,Store!$A$2:$A$181,Store!$B$2:$B$181,"Missing Store") -> FreshMart Mysuru Plaza | K269: =_xlfn.XLOOKUP(Sales_Transactions!$I269,Store!$A$2:$A$181,Store!$D$2:$D$181,"Missing Region") -> South | L269: EMP0104 | M269: Pandi Nair | N269: =_xlfn.XLOOKUP(Sales_Transactions!$L269,Table12[Employee_ID],Table12[Department],"Missing Department") -> Inventory | O269: 3 | P269: 246.7 | Q269: 0 | R269: 0 | S269: 740.1 | T269: 577.23 | U269: 162.87 | V269: Cash | W269: Not Returned | X269: In-Store | Y269: 20:11 | Z269: Weekday
A270: INV101740 | B270: 45941 | C270: CUST0049 | D270: =_xlfn.XLOOKUP(Sales_Transactions!$C270,Customer!$A$2:$A$701,Customer!$B$2:$B$701,"Missing") -> Lokesh Gupta | E270: =_xlfn.XLOOKUP(Table14[[#This Row],[Customer_ID]],Table10[Customer_ID],Table10[Membership],"Missing Membership") -> Gold | F270: PRD026 | G270: =_xlfn.XLOOKUP(Sales_Transactions!$F270,Products!$A$2:$A$151,Products!$B$2:$B$151,"missing product") -> Nescafe Coffee 1kg | H270: =_xlfn.XLOOKUP(Sales_Transactions!$F270,Table9[Product_ID],Table9[Category],"Missing Catogory") -> Beverages | I270: STR107 | J270: =_xlfn.XLOOKUP(Sales_Transactions!$I270,Store!$A$2:$A$181,Store!$B$2:$B$181,"Missing Store") -> FreshMart Surat Arcade | K270: =_xlfn.XLOOKUP(Sales_Transactions!$I270,Store!$A$2:$A$181,Store!$D$2:$D$181,"Missing Region") -> West | L270: EMP0038 | M270: Yamuna Achari | N270: =_xlfn.XLOOKUP(Sales_Transactions!$L270,Table12[Employee_ID],Table12[Department],"Missing Department") -> Inventory | O270: 4 | P270: 332.66 | Q270: 0 | R270: 0 | S270: 1530.24 | T270: 989 | U270: 541.24 | V270: Cash | W270: Not Returned | X270: In-Store | Y270: 16:40 | Z270: Weekend
A271: INV101741 | B271: 45764 | C271: CUST0123 | D271: =_xlfn.XLOOKUP(Sales_Transactions!$C271,Customer!$A$2:$A$701,Customer!$B$2:$B$701,"Missing") -> Sudha Rao | E271: =_xlfn.XLOOKUP(Table14[[#This Row],[Customer_ID]],Table10[Customer_ID],Table10[Membership],"Missing Membership") -> Bronze | F271: PRD056 | G271: =_xlfn.XLOOKUP(Sales_Transactions!$F271,Products!$A$2:$A$151,Products!$B$2:$B$151,"missing product") -> Cadbury Namkeen Combo | H271: =_xlfn.XLOOKUP(Sales_Transactions!$F271,Table9[Product_ID],Table9[Category],"Missing Catogory") -> Snacks | I271: STR041 | J271: =_xlfn.XLOOKUP(Sales_Transactions!$I271,Store!$A$2:$A$181,Store!$B$2:$B$181,"Missing Store") -> FreshMart Tiruppur Colony | K271: =_xlfn.XLOOKUP(Sales_Transactions!$I271,Store!$A$2:$A$181,Store!$D$2:$D$181,"Missing Region") -> South | L271: EMP0325 | M271: Chandran Naidu | N271: =_xlfn.XLOOKUP(Sales_Transactions!$L271,Table12[Employee_ID],Table12[Department],"Missing Department") -> Cashier | O271: 2 | P271: 333.54 | Q271: 0 | R271: 0 | S271: 667.08 | T271: 476.86 | U271: 190.22 | V271: Cash | W271: Not Returned | X271: Online | Y271: 19:54 | Z271: Weekday
A272: INV101747 | B272: 45837 | C272: CUST0686 | D272: =_xlfn.XLOOKUP(Sales_Transactions!$C272,Customer!$A$2:$A$701,Customer!$B$2:$B$701,"Missing") -> Hemalatha Balan | E272: =_xlfn.XLOOKUP(Table14[[#This Row],[Customer_ID]],Table10[Customer_ID],Table10[Membership],"Missing Membership") -> Gold | F272: PRD037 | G272: =_xlfn.XLOOKUP(Sales_Transactions!$F272,Products!$A$2:$A$151,Products!$B$2:$B$151,"missing product") -> ITC Frozen Snacks 250ml | H272: =_xlfn.XLOOKUP(Sales_Transactions!$F272,Table9[Product_ID],Table9[Category],"Missing Catogory") -> Frozen Foods | I272: STR006 | J272: =_xlfn.XLOOKUP(Sales_Transactions!$I272,Store!$A$2:$A$181,Store!$B$2:$B$181,"Missing Store") -> FreshMart Mysuru Junction | K272: =_xlfn.XLOOKUP(Sales_Transactions!$I272,Store!$A$2:$A$181,Store!$D$2:$D$181,"Missing Region") -> South | L272: EMP0265 | M272: Padma Subramaniam | N272: =_xlfn.XLOOKUP(Sales_Transactions!$L272,Table12[Employee_ID],Table12[Department],"Missing Department") -> Operations | O272: 8 | P272: 271.36 | Q272: 10 | R272: 217.09 | S272: 2246.86 | T272: 1675.04 | U272: 571.82 | V272: Cash | W272: Not Returned | X272: In-Store | Y272: 13:37 | Z272: Weekend
A273: INV101751 | B273: 45923 | C273: Customer Id Missing | D273: =_xlfn.XLOOKUP(Sales_Transactions!$C273,Customer!$A$2:$A$701,Customer!$B$2:$B$701,"Missing") -> Missing | E273: =_xlfn.XLOOKUP(Table14[[#This Row],[Customer_ID]],Table10[Customer_ID],Table10[Membership],"Missing Membership") -> Missing Membership | F273: PRD142 | G273: =_xlfn.XLOOKUP(Sales_Transactions!$F273,Products!$A$2:$A$151,Products!$B$2:$B$151,"missing product") -> Lizol Dishwash 200g | H273: =_xlfn.XLOOKUP(Sales_Transactions!$F273,Table9[Product_ID],Table9[Category],"Missing Catogory") -> Cleaning | I273: STR053 | J273: =_xlfn.XLOOKUP(Sales_Transactions!$I273,Store!$A$2:$A$181,Store!$B$2:$B$181,"Missing Store") -> FreshMart Tiruppur Heights | K273: =_xlfn.XLOOKUP(Sales_Transactions!$I273,Store!$A$2:$A$181,Store!$D$2:$D$181,"Missing Region") -> South | L273: EMP0133 | M273: Deepak Naicker | N273: =_xlfn.XLOOKUP(Sales_Transactions!$L273,Table12[Employee_ID],Table12[Department],"Missing Department") -> Sales | O273: 1 | P273: 522.78 | Q273: 10 | R273: 52.28 | S273: 470.5 | T273: 395.87 | U273: 74.63 | V273: Cash | W273: Not Returned | X273: Online | Y273: 16:18 | Z273: Weekday
A274: INV101754 | B274: 46016 | C274: CUST0587 | D274: =_xlfn.XLOOKUP(Sales_Transactions!$C274,Customer!$A$2:$A$701,Customer!$B$2:$B$701,"Missing") -> Uma Iyer | E274: =_xlfn.XLOOKUP(Table14[[#This Row],[Customer_ID]],Table10[Customer_ID],Table10[Membership],"Missing Membership") -> Bronze | F274: PRD024 | G274: =_xlfn.XLOOKUP(Sales_Transactions!$F274,Products!$A$2:$A$151,Products!$B$2:$B$151,"missing product") -> Aavin Milk Pack v2 | H274: =_xlfn.XLOOKUP(Sales_Transactions!$F274,Table9[Product_ID],Table9[Category],"Missing Catogory") -> Dairy | I274: STR136 | J274: =_xlfn.XLOOKUP(Sales_Transactions!$I274,Store!$A$2:$A$181,Store!$B$2:$B$181,"Missing Store") -> FreshMart Nagpur Crossing | K274: =_xlfn.XLOOKUP(Sales_Transactions!$I274,Store!$A$2:$A$181,Store!$D$2:$D$181,"Missing Region") -> West | L274: EMP0070 | M274: Umesh Subramaniam | N274: =_xlfn.XLOOKUP(Sales_Transactions!$L274,Table12[Employee_ID],Table12[Department],"Missing Department") -> Sales | O274: 1 | P274: 313.47 | Q274: 5 | R274: 15.67 | S274: 297.8 | T274: 246.12 | U274: 51.68 | V274: Cash | W274: Not Returned | X274: In-Store | Y274: 19:32 | Z274: Weekday
A275: INV101755 | B275: 45788 | C275: CUST0682 | D275: =_xlfn.XLOOKUP(Sales_Transactions!$C275,Customer!$A$2:$A$701,Customer!$B$2:$B$701,"Missing") -> Gopal Krishnan | E275: =_xlfn.XLOOKUP(Table14[[#This Row],[Customer_ID]],Table10[Customer_ID],Table10[Membership],"Missing Membership") -> Silver | F275: PRD009 | G275: =_xlfn.XLOOKUP(Sales_Transactions!$F275,Products!$A$2:$A$151,Products!$B$2:$B$151,"missing product") -> Harvest Gold Buns 200g | H275: =_xlfn.XLOOKUP(Sales_Transactions!$F275,Table9[Product_ID],Table9[Category],"Missing Catogory") -> Bakery | I275: STR077 | J275: =_xlfn.XLOOKUP(Sales_Transactions!$I275,Store!$A$2:$A$181,Store!$B$2:$B$181,"Missing Store") -> FreshMart Kochi Gardens | K275: =_xlfn.XLOOKUP(Sales_Transactions!$I275,Store!$A$2:$A$181,Store!$D$2:$D$181,"Missing Region") -> South | L275: EMP0030 | M275: Hariharan Rao | N275: =_xlfn.XLOOKUP(Sales_Transactions!$L275,Table12[Employee_ID],Table12[Department],"Missing Department") -> Cashier | O275: 4 | P275: 661.91 | Q275: 20 | R275: 529.53 | S275: 2435.83 | T275: 1594.88 | U275: 840.95 | V275: Cash | W275: Not Returned | X275: Online | Y275: 18:39 | Z275: Weekend
A276: INV101756 | B276: 46019 | C276: CUST0341 | D276: =_xlfn.XLOOKUP(Sales_Transactions!$C276,Customer!$A$2:$A$701,Customer!$B$2:$B$701,"Missing") -> Elango Sekar | E276: =_xlfn.XLOOKUP(Table14[[#This Row],[Customer_ID]],Table10[Customer_ID],Table10[Membership],"Missing Membership") -> Silver | F276: PRD030 | G276: =_xlfn.XLOOKUP(Sales_Transactions!$F276,Products!$A$2:$A$151,Products!$B$2:$B$151,"missing product") -> Nescafe Tea Combo | H276: =_xlfn.XLOOKUP(Sales_Transactions!$F276,Table9[Product_ID],Table9[Category],"Missing Catogory") -> Beverages | I276: STR071 | J276: =_xlfn.XLOOKUP(Sales_Transactions!$I276,Store!$A$2:$A$181,Store!$B$2:$B$181,"Missing Store") -> FreshMart Salem Crossing | K276: =_xlfn.XLOOKUP(Sales_Transactions!$I276,Store!$A$2:$A$181,Store!$D$2:$D$181,"Missing Region") -> South | L276: EMP0144 | M276: Chitra Nair | N276: =_xlfn.XLOOKUP(Sales_Transactions!$L276,Table12[Employee_ID],Table12[Department],"Missing Department") -> Cashier | O276: 4 | P276: 172.63 | Q276: 0 | R276: 0 | S276: 794.1 | T276: 568 | U276: 226.1 | V276: Cash | W276: Not Returned | X276: In-Store | Y276: 15:58 | Z276: Weekend
A277: INV101763 | B277: 45905 | C277: CUST0071 | D277: =_xlfn.XLOOKUP(Sales_Transactions!$C277,Customer!$A$2:$A$701,Customer!$B$2:$B$701,"Missing") -> Venkat Iyer | E277: =_xlfn.XLOOKUP(Table14[[#This Row],[Customer_ID]],Table10[Customer_ID],Table10[Membership],"Missing Membership") -> Silver | F277: PRD008 | G277: =_xlfn.XLOOKUP(Sales_Transactions!$F277,Products!$A$2:$A$151,Products!$B$2:$B$151,"missing product") -> Britannia Cookies 200g | H277: =_xlfn.XLOOKUP(Sales_Transactions!$F277,Table9[Product_ID],Table9[Category],"Missing Catogory") -> Bakery | I277: STR172 | J277: =_xlfn.XLOOKUP(Sales_Transactions!$I277,Store!$A$2:$A$181,Store!$B$2:$B$181,"Missing Store") -> FreshMart Guwahati Heights | K277: =_xlfn.XLOOKUP(Sales_Transactions!$I277,Store!$A$2:$A$181,Store!$D$2:$D$181,"Missing Region") -> East | L277: EMP0081 | M277: Radha Selvam | N277: =_xlfn.XLOOKUP(Sales_Transactions!$L277,Table12[Employee_ID],Table12[Department],"Missing Department") -> Sales | O277: 5 | P277: 455.79 | Q277: 0 | R277: 0 | S277: 2278.95 | T277: 1414.4 | U277: 864.55 | V277: Cash | W277: Not Returned | X277: In-Store | Y277: 13:28 | Z277: Weekday
A278: INV101766 | B278: 45832 | C278: CUST0442 | D278: =_xlfn.XLOOKUP(Sales_Transactions!$C278,Customer!$A$2:$A$701,Customer!$B$2:$B$701,"Missing") -> Kamala Rao | E278: =_xlfn.XLOOKUP(Table14[[#This Row],[Customer_ID]],Table10[Customer_ID],Table10[Membership],"Missing Membership") -> Silver | F278: PRD055 | G278: =_xlfn.XLOOKUP(Sales_Transactions!$F278,Products!$A$2:$A$151,Products!$B$2:$B$151,"missing product") -> Cadbury Biscuits Pack | H278: =_xlfn.XLOOKUP(Sales_Transactions!$F278,Table9[Product_ID],Table9[Category],"Missing Catogory") -> Snacks | I278: STR019 | J278: =_xlfn.XLOOKUP(Sales_Transactions!$I278,Store!$A$2:$A$181,Store!$B$2:$B$181,"Missing Store") -> FreshMart Hyderabad Heights | K278: =_xlfn.XLOOKUP(Sales_Transactions!$I278,Store!$A$2:$A$181,Store!$D$2:$D$181,"Missing Region") -> South | L278: EMP0064 | M278: Sanjay Venkataraman | N278: =_xlfn.XLOOKUP(Sales_Transactions!$L278,Table12[Employee_ID],Table12[Department],"Missing Department") -> Cashier | O278: 3 | P278: 125.15 | Q278: 20 | R278: 75.09 | S278: 300.36 | T278: 287.1 | U278: 13.26 | V278: Cash | W278: Not Returned | X278: In-Store | Y278: 10:45 | Z278: Weekday
... A589: INV101010 | B589: 45986 | C589: CUST0462 | D589: =_xlfn.XLOOKUP(Sales_Transactions!$C589,Customer!$A$2:$A$701,Customer!$B$2:$B$701,"Missing") -> Anitha Sharma | E589: =_xlfn.XLOOKUP(Table14[[#This Row],[Customer_ID]],Table10[Customer_ID],Table10[Membership],"Missing Membership") -> Silver | F589: PRD090 | G589: =_xlfn.XLOOKUP(Sales_Transactions!$F589,Products!$A$2:$A$151,Products!$B$2:$B$151,"missing product") -> Organic Fresh Fresh Fruits Pack v2 | H589: =_xlfn.XLOOKUP(Sales_Transactions!$F589,Table9[Product_ID],Table9[Category],"Missing Catogory") -> Fruits | I589: STR088 | J589: =_xlfn.XLOOKUP(Sales_Transactions!$I589,Store!$A$2:$A$181,Store!$B$2:$B$181,"Missing Store") -> FreshMart Salem Extension | K589: =_xlfn.XLOOKUP(Sales_Transactions!$I589,Store!$A$2:$A$181,Store!$D$2:$D$181,"Missing Region") -> South | L589: EMP0229 | M589: Udhay Sekar | N589: =_xlfn.XLOOKUP(Sales_Transactions!$L589,Table12[Employee_ID],Table12[Department],"Missing Department") -> Sales | O589: 1 | P589: 438.7 | Q589: 5 | R589: 21.93 | S589: 416.77 | T589: 370.18 | U589: 46.59 | V589: Credit Card | W589: Not Returned | X589: In-Store | Y589: 14:36 | Z589: Weekday
